2021-01-19 17:31:42,671 DEBUG    root            Loaded Command Group: ['gcloud', 'compute']
2021-01-19 17:31:42,676 DEBUG    root            Loaded Command Group: ['gcloud', 'compute', 'regions']
2021-01-19 17:31:42,691 DEBUG    root            Loaded Command Group: ['gcloud', 'compute', 'regions', 'list']
2021-01-19 17:31:42,696 DEBUG    root            Running [gcloud.compute.regions.list] with arguments: []
2021-01-19 17:31:42,906 DEBUG    google.auth.transport.requests Making request: POST https://oauth2.googleapis.com/token
2021-01-19 17:31:42,909 DEBUG    urllib3.connectionpool Starting new HTTPS connection (1): oauth2.googleapis.com:443
2021-01-19 17:31:43,973 DEBUG    urllib3.connectionpool https://oauth2.googleapis.com:443 "POST /token HTTP/1.1" 200 None
2021-01-19 17:31:44,395 INFO     root            Display format: "        table(
          name,
          quotas.metric.CPUS.quota():label=CPUS,
          quotas.metric.DISKS_TOTAL_GB.quota():label=DISKS_GB,
          quotas.metric.IN_USE_ADDRESSES.quota():label=ADDRESSES,
          quotas.metric.STATIC_ADDRESSES.quota():label=RESERVED_ADDRESSES,
          status():label=STATUS,
          deprecated.deleted:label=TURNDOWN_DATE
        )"
2021-01-19 17:31:44,403 DEBUG    urllib3.connectionpool Starting new HTTPS connection (1): compute.googleapis.com:443
2021-01-19 17:31:44,986 DEBUG    urllib3.connectionpool https://compute.googleapis.com:443 "POST /batch/compute/v1 HTTP/1.1" 200 None
2021-01-19 17:31:44,990 DEBUG    root            (gcloud.compute.regions.list) Some requests did not succeed:
 - Failed to find project opportune-epoch-301314
Traceback (most recent call last):
  File "/usr/lib64/google-cloud-sdk/lib/googlecloudsdk/calliope/cli.py", line 982, in Execute
    resources = calliope_command.Run(cli=self, args=args)
  File "/usr/lib64/google-cloud-sdk/lib/googlecloudsdk/calliope/backend.py", line 811, in Run
    display_info=self.ai.display_info).Display()
  File "/usr/lib64/google-cloud-sdk/lib/googlecloudsdk/calliope/display.py", line 483, in Display
    self._printer.Print(self._resources)
  File "/usr/lib64/google-cloud-sdk/lib/googlecloudsdk/core/resource/resource_printer_base.py", line 297, in Print
    for resource in resources:
  File "/usr/lib64/google-cloud-sdk/lib/googlecloudsdk/core/util/peek_iterable.py", line 211, in __next__
    item = self._NextItem()
  File "/usr/lib64/google-cloud-sdk/lib/googlecloudsdk/core/util/peek_iterable.py", line 183, in _NextItem
    return next(self._iterable)
  File "/usr/lib64/google-cloud-sdk/lib/googlecloudsdk/api_lib/compute/lister.py", line 922, in __call__
    utils.RaiseException(errors, ListException)
  File "/usr/lib64/google-cloud-sdk/lib/googlecloudsdk/api_lib/compute/utils.py", line 136, in RaiseException
    errors))
googlecloudsdk.api_lib.compute.lister.ListException: Some requests did not succeed:
 - Failed to find project opportune-epoch-301314

2021-01-19 17:31:44,998 ERROR    root            (gcloud.compute.regions.list) Some requests did not succeed:
 - Failed to find project opportune-epoch-301314

